Workbook

Sheet Dashboard
A1: BENGALURU BBA FRESHER | JOB INTELLIGENCE CONTROL TOWER
A2: Research snapshot: 11 Oct 2026 | Candidate: BBA International Business | Bengaluru | CV-matched operations/procurement/supply chain/business support; non-sales roles prioritised.
A3: 43 core role records plus 1 newly validated official Accenture addendum. 506 employers are targets, not confirmed vacancies. Use Verified Openings and Verified Addendum; re-open every link before applying. Official requisition IDs and public job-board IDs are different.
A5: Researched role records (incl. addendum) | C5: Employer target universe | E5: P1 / highest priority leads | G5: Official requisition IDs captured | I5: Search sources / portals | K5: Role families mapped
A6: 44 | C6: 506 | E6: 10 | G6: 22 | I6: 24 | K6: 39
A9: Recommended workflow: (1) sort Apply Now by weighted score; (2) use Verified Addendum for the new official Accenture Supply Chain Operations req AIOC-S01665657; (3) open source and reconfirm Apply status; (4) ask recruiter for written fixed/variable CTC and benefit eligibility; (5) request referrals using exact official IDs; (6) update Application Tracker v2; (7) use Research Prompt v3 in new employer batches and record all checks.
A11: Company target sectors | B11: Company count
A12: IT Services, Consulting & BPO | B12: =COUNTIF('Company Universe'!$C$5:$C$510,A12)
A13: Banking, Financial Services & Insurance | B13: =COUNTIF('Company Universe'!$C$5:$C$510,A13)
A14: Global Technology, SaaS & GCCs | B14: =COUNTIF('Company Universe'!$C$5:$C$510,A14)
A15: Industrial, Manufacturing, Automotive & Energy | B15: =COUNTIF('Company Universe'!$C$5:$C$510,A15)
A16: Retail, E-commerce, Logistics, Travel & Hospitality | B16: =COUNTIF('Company Universe'!$C$5:$C$510,A16)
A17: Healthcare, Pharma, Biotech & Life Sciences | B17: =COUNTIF('Company Universe'!$C$5:$C$510,A17)
A18: Education, Media, Marketing & Professional Platforms | B18: =COUNTIF('Company Universe'!$C$5:$C$510,A18)
A19: Bengaluru Startups & Scaleups | B19: =COUNTIF('Company Universe'!$C$5:$C$510,A19)
A20: Public Sector, Infrastructure & Utilities | B20: =COUNTIF('Company Universe'!$C$5:$C$510,A20)

Sheet Live Jobs
A1: LEGACY SNAPSHOT – EARLIER JOB LEADS (NOT THE CURRENT RANKED LIST)
A2: Historical starter list from the initial database. Use the Verified Openings sheet for the current 43 researched leads and the Application Tracker v2 for execution. Recheck job status/IDs before applying.
A4: Record ID | B4: Status / Evidence | C4: Priority | D4: Company / Employer | E4: Role Title | F4: Role Family | G4: Employment Type | H4: Location | I4: Education / Degree | J4: Experience Requirement | K4: Salary (source wording) | L4: Posted Date / Age (source wording) | M4: Closing Date | N4: Official Requisition ID | O4: Public Listing ID | P4: ID Type / Interpretation | Q4: Source Platform | R4: Official Career / ATS URL | S4: Direct Apply / Listing URL | T4: Role Snapshot | U4: BBA / Fresher Fit Evidence | V4: Key Skills / Keywords | W4: Work Mode / Shift | X4: Risks / Verification Needed | Y4: Date Last Checked | Z4: Next Recheck Date | AA4: Application Status | AB4: Referral Status | AC4: Referrer / Contact Notes | AD4: Source Confidence
A5: JOB-0001 | B5: Recent official listing - recheck before referral | C5: P1 - apply first | D5: Accenture | E5: Procure-to-Pay Operations New Associate | F5: Finance operations / P2P | G5: Full-time | H5: Bengaluru | I5: Any graduation (official listing) | J5: 0-1 years | K5: Not disclosed | L5: Posted 8 days ago (as indexed) | M5: Not stated | N5: AIOC-S01664684 | P5: Official requisition ID | Q5: Official Accenture careers | R5: https://accenture.wd103.myworkdayjobs.com/accenturecareers/job/Bengaluru/Procure-to-Pay-Operations-New-Associate_AIOC-S01664684-1 | S5: https://accenture.wd103.myworkdayjobs.com/accenturecareers/job/Bengaluru/Procure-to-Pay-Operations-New-Associate_AIOC-S01664684-1 | T5: Invoice processing, procure-to-pay, purchase-order matching, vendor-payment and finance operations activities. | U5: 5/5 - direct BBA fresher-friendly fit if graduation is complete and shift acceptable. | V5: Excel; accuracy; invoice validation; data quality; documentation; process discipline | W5: Full-time; shift may be rotational | X5: Re-open official page and confirm Apply button/availability; ask referrer to use exact req ID. | Y5: 2026-10-11 | Z5: 2026-10-12 | AA5: Not Started | AB5: Not Contacted | AD5: Official page indexed as posted 8 days ago
A6: JOB-0002 | B6: Recent official listing - recheck before referral | C6: P1 - apply first | D6: Accenture | E6: Procurement Practice New Associate | F6: Procurement operations | G6: Full-time | H6: Bengaluru | I6: Any graduation (official listing) | J6: 0-1 years | K6: Not disclosed | L6: Posted 15 days ago (as indexed) | M6: Not stated | N6: AIOC-S01664045 | P6: Official requisition ID | Q6: Official Accenture careers | R6: https://accenture.wd103.myworkdayjobs.com/en-US/AccentureCareers/job/Bengaluru-BDC9A/Procurement-Practice-New-Associate_AIOC-S01664045-1 | S6: https://accenture.wd103.myworkdayjobs.com/en-US/AccentureCareers/job/Bengaluru-BDC9A/Procurement-Practice-New-Associate_AIOC-S01664045-1 | T6: Tactical and transactional procurement, supplier/catalog maintenance, trackers, audit coordination and procurement process support. | U6: 5/5 - strong degree and experience match based on official posting. | V6: Excel; supplier coordination; procurement basics; audit trail; reporting; communication | W6: Full-time; possible rotational shift | X6: Confirm the listing remains open and whether BBA is accepted under Any Graduation. | Y6: 2026-10-11 | Z6: 2026-10-12 | AA6: Not Started | AB6: Not Contacted | AD6: Official page indexed today; posted 15 days ago
A7: JOB-0003 | B7: Portal indexed - recheck freshness | C7: P1/P2 - check current status | D7: Accenture | E7: Procurement Operations New Associate | F7: Procurement operations | G7: Full-time | H7: Bengaluru | I7: BCom / Any Graduation / B.B.M shown on one official version | J7: 0-1 years | K7: Not disclosed | L7: Indexed about 2 weeks ago | M7: Not stated | N7: AIOC-S01660136 | P7: Official requisition ID | Q7: Official Accenture careers | R7: https://www.accenture.com/in-en/careers/jobdetails?id=AIOC-S01660136_en | S7: https://www.accenture.com/in-en/careers/jobdetails?id=AIOC-S01660136_en | T7: Procurement support, supplier setup, purchase processes, documentation, audit support and SLA reporting. | U7: 5/5 if the requisition is still accepting applications. | V7: Procurement; Excel; reporting; attention to detail; teamwork | W7: Full-time; possible rotational shift | X7: Re-open official page; multiple similar Accenture requisitions exist, so avoid duplicate referrals if already submitted. | Y7: 2026-10-11 | Z7: 2026-10-12 | AA7: Not Started | AB7: Not Contacted | AD7: Official result crawled recently; exact status must be reconfirmed
A8: JOB-0004 | B8: Official listing indexed - older, verify open/closed | C8: P2 - verify first | D8: Accenture | E8: Procure to Pay Operations New Associate | F8: Finance operations / P2P | G8: Full-time | H8: Bengaluru | I8: BCom / B.B.M (official listing) | J8: 0-1 years | K8: Not disclosed | L8: Posted 30+ days ago (indexed) | M8: Not stated | N8: AIOC-S01661384 | P8: Official requisition ID | Q8: Official Accenture careers | R8: https://accenture.wd103.myworkdayjobs.com/en-US/AccentureCareers/job/Bengaluru/Procure-to-Pay-Operations-New-Associate_AIOC-S01661384-1 | S8: https://accenture.wd103.myworkdayjobs.com/en-US/AccentureCareers/job/Bengaluru/Procure-to-Pay-Operations-New-Associate_AIOC-S01661384-1 | T8: Procure-to-pay and invoice processing role in finance operations. | U8: 4/5 - BBA may fit only if the role accepts B.B.M/related degree; confirm BBA is accepted. | V8: Invoice processing; Excel; data accuracy; vendor payment; documentation | W8: Full-time; possible rotational shift | X8: Older result. Confirm active status and BBA eligibility before referral. | Y8: 2026-10-11 | Z8: 2026-10-12 | AA8: Not Started | AB8: Not Contacted | AD8: Older official posting; do not treat as open until reconfirmed
A9: JOB-0005 | B9: Recent official listing - recheck before referral | C9: P1 - apply first | D9: EY | E9: Associate - Resource Management | F9: Workforce / business operations | G9: Full-time | H9: Bengaluru | I9: Degree requirements: review official JD | J9: 0-3 years reported; confirm exact requirement | K9: Competitive / not quantified | L9: 2026-10-08 | M9: Not stated | N9: 1739823 | P9: Official requisition ID | Q9: Official EY careers | R9: https://careers.ey.com/ey/job/Bengaluru-Associate-Resource-Management-KA-560048/1445690033/ | S9: https://careers.ey.com/ey/job/Bengaluru-Associate-Resource-Management-KA-560048/1445690033/ | T9: Resource scheduling, resource requests, utilisation reporting, stakeholder updates and resolving scheduling conflicts. | U9: 4/5 - good business coordination fit; verify BBA eligibility and Excel expectations. | V9: Advanced Excel; planning; data tracking; stakeholder management; reporting; prioritisation | W9: Full-time; location Bengaluru | X9: Official page dates the posting 8 Oct 2026; re-open role and confirm requirements before asking for referral. | Y9: 2026-10-11 | Z9: 2026-10-12 | AA9: Not Started | AB9: Not Contacted | AD9: Official posting dated 2026-10-08
A10: JOB-0006 | B10: Recent official ATS listing | C10: P1 - apply first | D10: Allegis Global Solutions | E10: Onboarding Associate - APAC Shift - Supply Chain / SCM | F10: Supplier onboarding / procurement operations | G10: Full-time | H10: Bengaluru; hybrid (Mon-Wed office noted) | I10: Bachelor's degree or related major/equivalent business experience | J10: Prior related experience is an advantage; internships/academic coordination can be considered | K10: Not disclosed | L10: Published date not disclosed; indexed yesterday | M10: Not stated | N10: 744000152372369 | O10: 4471701540 (LinkedIn listing reference from prior search) | P10: Official SmartRecruiters posting ID + public LinkedIn listing ID | Q10: Official SmartRecruiters / Allegis Global Solutions | R10: https://jobs.smartrecruiters.com/AllegisGlobalSolutions/744000152372369-onboarding-associate-apac-shift-supply-chain-scm-bengaluru | S10: https://jobs.smartrecruiters.com/AllegisGlobalSolutions/744000152372369-onboarding-associate-apac-shift-supply-chain-scm-bengaluru | T10: Supplier vetting/onboarding, document checking, compliance, trackers, reporting, escalations and cross-team coordination. | U10: 5/5 - coordination and documentation align well; internship/event coordination can help demonstrate stakeholder skills. | V10: Documentation; vendor follow-up; compliance; Excel; trackers; stakeholder communication; SLAs | W10: Hybrid; 10:00 AM-7:00 PM APAC shift shown | X10: Confirm current status and whether the LinkedIn ID points to this exact APAC variant before sending. | Y10: 2026-10-11 | Z10: 2026-10-12 | AA10: Not Started | AB10: Not Contacted | AD10: Official ATS page indexed yesterday
A11: JOB-0007 | B11: Recent official ATS listing | C11: P1/P2 - check shift preference | D11: Allegis Global Solutions | E11: Onboarding Associate - Meta (Global) - Supply Chain / SCM | F11: Supplier onboarding / procurement operations | G11: Full-time | H11: Bengaluru; hybrid | I11: Bachelor's degree or related major/equivalent business experience | J11: Relevant internship/academic coordination can be considered; prior experience an advantage | K11: Not disclosed | L11: Published date not disclosed; indexed today | M11: Not stated | N11: 744000151812601 | P11: Official SmartRecruiters posting ID | Q11: Official SmartRecruiters / Allegis Global Solutions | R11: https://jobs.smartrecruiters.com/allegisglobalsolutions/744000151812601 | S11: https://jobs.smartrecruiters.com/allegisglobalsolutions/744000151812601 | T11: Supplier onboarding and compliance; document collection, follow-ups, trackers, quality checks and process improvement. | U11: 4/5 - BBA-friendly coordination profile; later shift is the main consideration. | V11: Documentation; vendor coordination; Excel; data accuracy; compliance; written communication | W11: Hybrid; 3:00 PM-12:00 AM shift shown | X11: Confirm shift, posting status and exact live ID with employee. | Y11: 2026-10-11 | Z11: 2026-10-12 | AA11: Not Started | AB11: Not Contacted | AD11: Official ATS page indexed today
A12: JOB-0008 | B12: Third-party listing - fresher eligibility stated | C12: P1/P2 - refer after portal check | D12: JPMorgan Chase | E12: Business and Operations Specialist | F12: Business operations / vendor payments | G12: Full-time | H12: Bengaluru | I12: Review full listing; BBA eligibility not expressly verified in compact data | J12: Freshers can apply (public listing) | K12: Not disclosed | L12: Date not exposed in retrieved Apna data | M12: Not stated | N12: Not exposed | O12: 1129984729 | P12: Public Apna listing ID (not internal requisition) | Q12: Apna job board | R12: https://careers.jpmorgan.com/global/en | S12: https://apna.co/job/bengaluru-bangalore/business-and-operations-specialist-1129984729 | T12: Invoice validation, vendor-payment requests, mailbox monitoring, operational trackers, audit-ready records and issue resolution. | U12: 4/5 - business process work aligns well; verify exact degree requirement and that the role remains open. | V12: Excel; invoice checking; documentation; process adherence; query handling; detail orientation | W12: Full-time; exact shift not verified | X12: Ask employee to find this title or equivalent on JPMC's internal careers portal; do not use the Apna ID as a JPMC requisition. | Y12: 2026-10-11 | Z12: 2026-10-12 | AA12: Not Started | AB12: Not Contacted | AD12: Job-board indexed; official requisition/status unknown
A13: JOB-0009 | B13: Third-party listing - fresher-only stated | C13: P1 - apply after status check | D13: Marriott International / Marriott Hotels India | E13: Purchase Associate | F13: Purchasing / hotel operations | G13: Full-time | H13: Bengaluru | I13: Confirm exact degree requirements in full JD | J13: Freshers only (Apna listing) | K13: Not disclosed | L13: Date not exposed in retrieved Apna data | M13: Not stated | N13: Not exposed | O13: 1912459795 | P13: Public Apna listing ID (not internal requisition) | Q13: Apna job board | R13: https://careers.marriott.com/ | S13: https://apna.co/job/bengaluru-bangalore/purchase-associate-1912459795 | T13: Inventory and order records, invoices, requisitions, stock monitoring, receiving reports and supplier-delivery issue follow-up. | U13: 4/5 - purchasing and operations are direct BBA-adjacent functions; hospitality shift/physical duties may apply. | V13: Inventory; Excel; invoice reconciliation; purchase requisitions; vendor follow-up; recordkeeping | W13: On-site likely; confirm with employer | X13: Search Marriott's official portal for the same role/location; confirm the Apna listing still exists. | Y13: 2026-10-11 | Z13: 2026-10-12 | AA13: Not Started | AB13: Not Contacted | AD13: Job-board indexed; official requisition/status unknown
A14: JOB-0010 | B14: Third-party listing - fresher eligibility stated | C14: P1/P2 - refer after verification | D14: KPMG India Services | E14: Business Associate - Quality and Risk Management | F14: Risk / quality / research operations | G14: Full-time | H14: Bengaluru | I14: Full degree/field requirements need full JD review | J14: Freshers can apply (Apna listing) | K14: Not disclosed | L14: Date not exposed in retrieved Apna data | M14: Not stated | N14: Not exposed | O14: 1779532141 | P14: Public Apna listing ID (not internal requisition) | Q14: Apna job board | R14: https://kpmg.com/in/en/home/careers.html | S14: https://apna.co/job/bengaluru-bangalore/business-associate-quality-and-risk-management-1779532141 | T14: Corporate/database research, regulatory and risk checks, research databases, offshore stakeholder updates and project execution. | U14: 4/5 - good fit if BBA is accepted and candidate can show research, documentation and professional communication. | V14: Online research; Excel; written communication; risk awareness; attention to detail; reporting | W14: Full-time; possible international team schedule | X14: Find matching posting on official KPMG portal or confirm with employee; public job-board ID is not an internal requisition. | Y14: 2026-10-11 | Z14: 2026-10-12 | AA14: Not Started | AB14: Not Contacted | AD14: Job-board indexed; official requisition/status unknown
A15: JOB-0011 | B15: Third-party listing - fresher-only stated | C15: P2 - review full JD | D15: Altisource | E15: Associate (Granite) | F15: Business / financial operations | G15: Full-time | H15: Bengaluru | I15: Not fully confirmed in compact listing | J15: Freshers only (Apna listing) | K15: Not disclosed | L15: Date not exposed in retrieved Apna data | M15: Not stated | N15: Not exposed | O15: 1340046698 | P15: Public Apna listing ID (not internal requisition) | Q15: Apna job board | R15: https://www.altisource.com/careers | S15: https://apna.co/job/bengaluru-bangalore/associate-1340046698 | T15: Listing describes executive-facing work organizing financial strategy for business lines; inspect role scope closely. | U15: 3/5 - possible business role, but specific analytical/financial requirements need a careful check. | V15: Excel; financial/operational analysis; documentation; communication | W15: Confirm with employer | X15: Confirm the exact degree, work scope and active status from official employer channel. | Y15: 2026-10-11 | Z15: 2026-10-12 | AA15: Not Started | AB15: Not Contacted | AD15: Job-board indexed; eligibility and official req unknown
A16: JOB-0012 | B16: Third-party listing - fresher-only internship | C16: P2 - internship pathway | D16: Pearson | E16: HR Operations Associate Intern | F16: HR operations / people services | G16: Internship | H16: Bengaluru; Cunningham Road listed | I16: Review full official JD | J16: Freshers only (Apna listing) | K16: Not disclosed | L16: Date not exposed in retrieved Apna data | M16: Not stated | N16: Not exposed | O16: 1682511397 | P16: Public Apna listing ID (not internal requisition) | Q16: Apna job board | R16: https://pearson.jobs/ | S16: https://apna.co/job/bengaluru-bangalore/hr-operations-associate-intern-1682511397 | T16: Internship supports HR operations and real projects; source displayed an unusual duration field, which needs checking. | U16: 4/5 - good bridge into HR operations if internship duration and stipend work for you. | V16: Excel; employee data handling; HR administration; confidentiality; coordination | W16: Likely on-site; verify | X16: Check stipend, duration and whether this is an active requisition on Pearson's own career portal. | Y16: 2026-10-11 | Z16: 2026-10-12 | AA16: Not Started | AB16: Not Contacted | AD16: Job-board indexed; duration field inconsistent/verify
A17: JOB-0013 | B17: Third-party listing - apprenticeship | C17: P2 - structured entry path | D17: Deutsche Bank | E17: Human Resources Apprentice (2026-2027) | F17: HR operations / apprenticeship | G17: 12-month apprenticeship | H17: Bengaluru; listing also names Mumbai and Pune | I17: Check official apprenticeship eligibility and passing-year rules | J17: Freshers only (Apna listing) | K17: Not disclosed in retrieved listing | L17: Date not exposed in retrieved Apna data | M17: Not stated | N17: Not exposed | O17: 1125222884 | P17: Public Apna listing ID (not internal requisition) | Q17: Apna job board | R17: https://careers.db.com/professionals/search-roles/ | S17: https://apna.co/job/bengaluru-bangalore/human-resources-apprentice-1125222884 | T17: 12-month apprenticeship with structured on-the-job HR learning; source says permanent employment is not guaranteed afterward. | U17: 4/5 - relevant to BBA if the programme accepts your batch, degree and apprenticeship eligibility. | V17: HR administration; communication; Excel; confidentiality; coordination | W17: Full-time apprenticeship; confirm in-office requirements | X17: Check age/batch/NATS eligibility, stipend and active official role. Not a guaranteed permanent job. | Y17: 2026-10-11 | Z17: 2026-10-12 | AA17: Not Started | AB17: Not Contacted | AD17: Public listing indexed; official req/status unknown
A18: JOB-0014 | B18: Third-party listing - fresher-only internship | C18: P2 - internship pathway | D18: Intugine Technologies | E18: Operations Intern - Reverse Logistics | F18: Logistics / operations / supply chain | G18: Internship | H18: Bengaluru | I18: Not fully specified in compact listing | J18: Freshers only (Apna listing) | K18: Not disclosed | L18: Date not exposed in retrieved Apna data | M18: Not stated | N18: Not exposed | O18: 1694554752 | P18: Public Apna listing ID (not internal requisition) | Q18: Apna job board | R18: https://intugine.com/careers/ | S18: https://apna.co/job/bengaluru-bangalore/operations-intern-reverse-logistics-1694554752 | T18: Supports reverse-logistics and supply-chain operations; useful path into logistics-tech and operations. | U18: 4/5 - good relevant exposure if stipend and timing are suitable. | V18: Operations coordination; Excel; data tracking; logistics; problem solving | W18: Confirm with employer | X18: Confirm active status, duration, stipend and possible full-time conversion. | Y18: 2026-10-11 | Z18: 2026-10-12 | AA18: Not Started | AB18: Not Contacted | AD18: Job-board indexed; official requisition/status unknown
A19: JOB-0015 | B19: Freshly indexed third-party listing | C19: P1 - apply now after quick check | D19: SharePal | E19: Associate - Purchase - Fresher | F19: Purchasing / procurement | G19: Full-time | H19: Bengaluru | I19: Review employer's JD | J19: No experience required | K19: ₹4,00,000-₹5,00,000/year listed | L19: Posted 1 week ago | M19: Not stated | N19: Not exposed | O19: 1790684619 (embedded in Internshala URL) | P19: Public Internshala listing reference; not an internal requisition | Q19: Internshala | R19: https://www.google.com/search?q=SharePal+official+careers+Bengaluru | S19: https://internshala.com/job/detail/fresher-associate-purchase-job-in-bangalore-at-sharepal1790684619/ | T19: Entry-level purchase associate role in Bengaluru; source indicated no experience required and ₹4-5 LPA. | U19: 5/5 - strong fit for procurement/purchasing preferences, subject to requirements and job still open. | V19: Purchase coordination; Excel; vendor follow-up; communication; documentation | W19: Confirm on listing | X19: 242 applicants were shown when indexed; apply quickly and verify company legitimacy, role details and application deadline. | Y19: 2026-10-11 | Z19: 2026-10-12 | AA19: Not Started | AB19: Not Contacted | AD19: Posted about 1 week ago on Internshala
A20: JOB-0016 | B20: Recent third-party listing | C20: P1/P2 - verify call-based elements | D20: Nathaniel School of Music | E20: Student Support & Operations Executive - Fresher | F20: Education / student operations | G20: Full-time | H20: Bengaluru | I20: BBA-compatible on face of title; verify JD | J20: No experience required | K20: ₹3,60,000-₹4,20,000/year listed | L20: Posted 1 week ago | M20: Not stated | N20: Not exposed | O20: 1790600518 (embedded in Internshala URL) | P20: Public Internshala listing reference | Q20: Internshala | R20: https://www.google.com/search?q=Nathaniel+School+of+Music+careers | S20: https://internshala.com/job/detail/fresher-student-support-operations-executive-job-in-bangalore-at-nathaniel-school-of-music1790600518/ | T20: Student support and operations work in an education organisation. | U20: 4/5 - communication and coordination experience is relevant; assess voice/call responsibilities before applying. | V20: Student/customer operations; scheduling; communication; documentation; issue resolution | W20: Confirm with employer | X20: Review job description, role's call-based component, exact hours and salary structure. | Y20: 2026-10-11 | Z20: 2026-10-12 | AA20: Not Started | AB20: Not Contacted | AD20: Posted about 1 week ago on Internshala
A21: JOB-0017 | B21: Recent third-party listing | C21: P2 - verify scope | D21: Nathaniel School of Music | E21: Operations & Admin Executive (Education) - Fresher | F21: Administration / education operations | G21: Full-time | H21: Bengaluru | I21: BBA-compatible on face of title; verify JD | J21: No experience required | K21: ₹3,00,000-₹4,20,000/year listed | L21: Posted 5 days ago | M21: Not stated | N21: Not exposed | O21: 1791182216 (embedded in Internshala URL) | P21: Public Internshala listing reference | Q21: Internshala | R21: https://www.google.com/search?q=Nathaniel+School+of+Music+careers | S21: https://internshala.com/job/detail/fresher-operations-admin-executive-education-job-in-bangalore-at-nathaniel-school-of-music1791182216/ | T21: Operations and administrative support for an education organisation. | U21: 4/5 - event coordination, team supervision and documentation can be framed as relevant experience. | V21: Administrative operations; scheduling; recordkeeping; Excel; communication | W21: Confirm with employer | X21: Verify role scope, employer details, compensation structure and whether there are sales targets. | Y21: 2026-10-11 | Z21: 2026-10-12 | AA21: Not Started | AB21: Not Contacted | AD21: Posted about 5 days ago on Internshala
A22: JOB-0018 | B22: Recent third-party listing - role scope check | C22: P3 - verify title/scope carefully | D22: Soul Staje | E22: Operations Manager - Fresher | F22: Operations | G22: Full-time | H22: Bengaluru | I22: Review full listing | J22: No experience required listed | K22: ₹2,60,000-₹3,90,000/year listed | L22: Posted 1 day ago | M22: Not stated | N22: Not exposed | O22: 1791557235 (embedded in Internshala URL) | P22: Public Internshala listing reference | Q22: Internshala | R22: https://www.google.com/search?q=Soul+Staje+official+careers | S22: https://internshala.com/job/detail/fresher-operations-manager-job-in-bangalore-at-soul-staje1791557235/ | T22: Title says Operations Manager but listing is tagged fresher; likely needs detailed scope verification. | U22: 2/5 - title and fresher tag are unusual; compare actual responsibilities before investing time. | V22: Operations coordination; process tracking; communication | W22: Confirm with employer | X22: Treat as lower confidence until employer identity, manager scope, salary and reporting line are confirmed. | Y22: 2026-10-11 | Z22: 2026-10-12 | AA22: Not Started | AB22: Not Contacted | AD22: Posted about 1 day ago on Internshala
A23: JOB-0019 | B23: Third-party listing - older, recheck open/closed | C23: P2 - recheck status | D23: Prosperr.io | E23: Operation Support Associate | F23: Business operations / customer operations | G23: Full-time | H23: Bengaluru | I23: Bachelor's degree may be suitable; confirm full JD | J23: Freshers and 0-3 years described in listing/search context | K23: ₹3 LPA onwards previously indexed; confirm current listing | L23: 2026-09-12 | M23: Not stated | N23: Not exposed | O23: JOBSEARCH_100681 (Indeed internal result ref, not public requisition) | P23: Indeed result reference; no public requisition ID exposed | Q23: Indeed | R23: https://www.google.com/search?q=Prosperr.io+careers+Bengaluru | S23: https://to.indeed.com/aacxlw2cqb9c | T23: Operational data, reports, dashboards, customer operations support and cross-team coordination. | U23: 4/5 - likely good operations path, but the listing is around a month old. | V23: Excel/Google Sheets; reporting; dashboards; coordination; written communication | W23: Confirm with employer | X23: Open listing and confirm still active before referral; do not treat Indeed result key as a company job ID. | Y23: 2026-10-11 | Z23: 2026-10-12 | AA23: Not Started | AB23: Not Contacted | AD23: Posted 2026-09-12; stale until reconfirmed
... A27: JOB-0023 | B27: Recent third-party listing - role match possible | C27: P2 - verify experience | D27: NITSHAW | E27: Service and Purchase Coordinator | F27: Purchasing / service operations | G27: Full-time (verify) | H27: Bengaluru | I27: Not exposed in compact listing | J27: Not confirmed | K27: Not exposed | L27: 2026-09-21 | M27: Not stated | N27: Not exposed | O27: JOBSEARCH_100693 (Indeed internal result ref, not public requisition) | P27: Indeed result reference; no public requisition ID exposed | Q27: Indeed | R27: https://www.google.com/search?q=NITSHAW+careers+Bengaluru | S27: https://to.indeed.com/aamp4t7ygf72 | T27: Service operations and purchase coordination, potentially relevant to vendor follow-up and documentation experience. | U27: 3/5 - consider only after checking qualifications and whether fresher applications are accepted. | V27: Purchase coordination; vendor follow-up; documentation; service operations | W27: Confirm on-site/hybrid | X27: Listing posted in September; check if still open and obtain full JD. | Y27: 2026-10-11 | Z27: 2026-10-12 | AA27: Not Started | AB27: Not Contacted | AD27: Posted 2026-09-21; reconfirm

Sheet Company Universe
A1: BENGALURU COMPANY TARGET UNIVERSE | 500+ EMPLOYERS
A2: A broad prospecting universe across MNCs, GCCs, Indian enterprises, financial services, industrials and startups. Each row is a company target, not evidence of an active vacancy or verified local office.
A4: Company ID | B4: Company Name | C4: Sector | D4: Employer Type / Segment | E4: Bengaluru Footprint Confidence | F4: Fortune / Enterprise Classification | G4: BBA-Friendly Role Families to Search | H4: Target Priority | I4: Career Portal / Discovery URL | J4: URL Type | K4: Bengaluru Role Search Shortcut | L4: Vacancy Evidence Status | M4: Last Portal Check | N4: ATS / Platform if known | O4: Next Search Plan | P4: Research Notes
A5: CO-0001 | B5: Accenture | C5: IT Services, Consulting & BPO | D5: MNC / professional services | E5: Strong or plausible Bengaluru hiring ecosystem; verify role location | F5: Fortune-scale global enterprise / likely annual-list candidate; verify exact current list & rank | G5: Business operations; process associate; PMO; procurement; finance operations; HR operations; workforce coordination; client/service delivery support; research; digital marketing operations | H5: P1 - start here | I5: https://www.accenture.com/in-en/careers | J5: Official careers page | K5: https://www.google.com/search?q=Accenture+Bengaluru+Bangalore+entry+level+careers+operations+procurement+HR+jobs | L5: Company target only - no current vacancy independently verified in company-universe scan | M5: Not checked in this build | O5: Re-check every 7 days; check official portal first, then ATS / LinkedIn / job boards | P5: Company target only; this row is not proof of a live vacancy. Search exact Bengaluru location, filter by 0-2 years and degree eligibility, then record a verified requisition in Live Jobs.
A6: CO-0002 | B6: Capgemini | C6: IT Services, Consulting & BPO | D6: MNC / professional services | E6: Strong or plausible Bengaluru hiring ecosystem; verify role location | F6: Global enterprise; check latest Fortune US 500 / Global 500 / 1000 lists | G6: Business operations; process associate; PMO; procurement; finance operations; HR operations; workforce coordination; client/service delivery support; research; digital marketing operations | H6: P1 | I6: https://www.capgemini.com/in-en/careers/ | J6: Official careers page | K6: https://www.google.com/search?q=Capgemini+Bengaluru+Bangalore+entry+level+careers+operations+procurement+HR+jobs | L6: Company target only - no current vacancy independently verified in company-universe scan | M6: Not checked in this build | O6: Re-check every 7 days; check official portal first, then ATS / LinkedIn / job boards | P6: Company target only; this row is not proof of a live vacancy. Search exact Bengaluru location, filter by 0-2 years and degree eligibility, then record a verified requisition in Live Jobs.
A7: CO-0003 | B7: Tata Consultancy Services (TCS) | C7: IT Services, Consulting & BPO | D7: MNC / professional services | E7: Strong or plausible Bengaluru hiring ecosystem; verify role location | F7: Global enterprise; check latest Fortune US 500 / Global 500 / 1000 lists | G7: Business operations; process associate; PMO; procurement; finance operations; HR operations; workforce coordination; client/service delivery support; research; digital marketing operations | H7: P1 | I7: https://www.tcs.com/careers | J7: Official careers page | K7: https://www.google.com/search?q=Tata+Consultancy+Services+%28TCS%29+Bengaluru+Bangalore+entry+level+careers+operations+procurement+HR+jobs | L7: Company target only - no current vacancy independently verified in company-universe scan | M7: Not checked in this build | O7: Re-check every 7 days; check official portal first, then ATS / LinkedIn / job boards | P7: Company target only; this row is not proof of a live vacancy. Search exact Bengaluru location, filter by 0-2 years and degree eligibility, then record a verified requisition in Live Jobs.
A8: CO-0004 | B8: Infosys | C8: IT Services, Consulting & BPO | D8: MNC / professional services | E8: Strong or plausible Bengaluru hiring ecosystem; verify role location | F8: Global enterprise; check latest Fortune US 500 / Global 500 / 1000 lists | G8: Business operations; process associate; PMO; procurement; finance operations; HR operations; workforce coordination; client/service delivery support; research; digital marketing operations | H8: P1 | I8: https://www.infosys.com/careers/ | J8: Official careers page | K8: https://www.google.com/search?q=Infosys+Bengaluru+Bangalore+entry+level+careers+operations+procurement+HR+jobs | L8: Company target only - no current vacancy independently verified in company-universe scan | M8: Not checked in this build | O8: Re-check every 7 days; check official portal first, then ATS / LinkedIn / job boards | P8: Company target only; this row is not proof of a live vacancy. Search exact Bengaluru location, filter by 0-2 years and degree eligibility, then record a verified requisition in Live Jobs.
A9: CO-0005 | B9: Wipro | C9: IT Services, Consulting & BPO | D9: MNC / professional services | E9: Strong or plausible Bengaluru hiring ecosystem; verify role location | F9: Global enterprise; check latest Fortune US 500 / Global 500 / 1000 lists | G9: Business operations; process associate; PMO; procurement; finance operations; HR operations; workforce coordination; client/service delivery support; research; digital marketing operations | H9: P1 | I9: https://careers.wipro.com/ | J9: Official careers page | K9: https://www.google.com/search?q=Wipro+Bengaluru+Bangalore+entry+level+careers+operations+procurement+HR+jobs | L9: Company target only - no current vacancy independently verified in company-universe scan | M9: Not checked in this build | O9: Re-check every 7 days; check official portal first, then ATS / LinkedIn / job boards | P9: Company target only; this row is not proof of a live vacancy. Search exact Bengaluru location, filter by 0-2 years and degree eligibility, then record a verified requisition in Live Jobs.
A10: CO-0006 | B10: Cognizant | C10: IT Services, Consulting & BPO | D10: MNC / professional services | E10: Strong or plausible Bengaluru hiring ecosystem; verify role location | F10: Global enterprise; check latest Fortune US 500 / Global 500 / 1000 lists | G10: Business operations; process associate; PMO; procurement; finance operations; HR operations; workforce coordination; client/service delivery support; research; digital marketing operations | H10: P1 | I10: https://careers.cognizant.com/india-en/ | J10: Official careers page | K10: https://www.google.com/search?q=Cognizant+Bengaluru+Bangalore+entry+level+careers+operations+procurement+HR+jobs | L10: Company target only - no current vacancy independently verified in company-universe scan | M10: Not checked in this build | O10: Re-check every 7 days; check official portal first, then ATS / LinkedIn / job boards | P10: Company target only; this row is not proof of a live vacancy. Search exact Bengaluru location, filter by 0-2 years and degree eligibility, then record a verified requisition in Live Jobs.
A11: CO-0007 | B11: HCLTech | C11: IT Services, Consulting & BPO | D11: MNC / professional services | E11: Strong or plausible Bengaluru hiring ecosystem; verify role location | F11: Global enterprise; check latest Fortune US 500 / Global 500 / 1000 lists | G11: Business operations; process associate; PMO; procurement; finance operations; HR operations; workforce coordination; client/service delivery support; research; digital marketing operations | H11: P1 | I11: https://www.hcltech.com/careers | J11: Official careers page | K11: https://www.google.com/search?q=HCLTech+Bengaluru+Bangalore+entry+level+careers+operations+procurement+HR+jobs | L11: Company target only - no current vacancy independently verified in company-universe scan | M11: Not checked in this build | O11: Re-check every 7 days; check official portal first, then ATS / LinkedIn / job boards | P11: Company target only; this row is not proof of a live vacancy. Search exact Bengaluru location, filter by 0-2 years and degree eligibility, then record a verified requisition in Live Jobs.
A12: CO-0008 | B12: Tech Mahindra | C12: IT Services, Consulting & BPO | D12: MNC / professional services | E12: Strong or plausible Bengaluru hiring ecosystem; verify role location | F12: Global enterprise; check latest Fortune US 500 / Global 500 / 1000 lists | G12: Business operations; process associate; PMO; procurement; finance operations; HR operations; workforce coordination; client/service delivery support; research; digital marketing operations | H12: P1 | I12: https://www.techmahindra.com/careers/ | J12: Official careers page | K12: https://www.google.com/search?q=Tech+Mahindra+Bengaluru+Bangalore+entry+level+careers+operations+procurement+HR+jobs | L12: Company target only - no current vacancy independently verified in company-universe scan | M12: Not checked in this build | O12: Re-check every 7 days; check official portal first, then ATS / LinkedIn / job boards | P12: Company target only; this row is not proof of a live vacancy. Search exact Bengaluru location, filter by 0-2 years and degree eligibility, then record a verified requisition in Live Jobs.
A13: CO-0009 | B13: LTIMindtree | C13: IT Services, Consulting & BPO | D13: MNC / professional services | E13: Strong or plausible Bengaluru hiring ecosystem; verify role location | F13: Global enterprise; check latest Fortune US 500 / Global 500 / 1000 lists | G13: Business operations; process associate; PMO; procurement; finance operations; HR operations; workforce coordination; client/service delivery support; research; digital marketing operations | H13: P1 | I13: https://www.ltimindtree.com/careers/ | J13: Official careers page | K13: https://www.google.com/search?q=LTIMindtree+Bengaluru+Bangalore+entry+level+careers+operations+procurement+HR+jobs | L13: Company target only - no current vacancy independently verified in company-universe scan | M13: Not checked in this build | O13: Re-check every 7 days; check official portal first, then ATS / LinkedIn / job boards | P13: Company target only; this row is not proof of a live vacancy. Search exact Bengaluru location, filter by 0-2 years and degree eligibility, then record a verified requisition in Live Jobs.
A14: CO-0010 | B14: Mphasis | C14: IT Services, Consulting & BPO | D14: MNC / professional services | E14: Strong or plausible Bengaluru hiring ecosystem; verify role location | F14: Global enterprise; check latest Fortune US 500 / Global 500 / 1000 lists | G14: Business operations; process associate; PMO; procurement; finance operations; HR operations; workforce coordination; client/service delivery support; research; digital marketing operations | H14: P1 | I14: https://careers.mphasis.com/ | J14: Official careers page | K14: https://www.google.com/search?q=Mphasis+Bengaluru+Bangalore+entry+level+careers+operations+procurement+HR+jobs | L14: Company target only - no current vacancy independently verified in company-universe scan | M14: Not checked in this build | O14: Re-check every 7 days; check official portal first, then ATS / LinkedIn / job boards | P14: Company target only; this row is not proof of a live vacancy. Search exact Bengaluru location, filter by 0-2 years and degree eligibility, then record a verified requisition in Live Jobs.
A15: CO-0011 | B15: Genpact | C15: IT Services, Consulting & BPO | D15: MNC / professional services | E15: Strong or plausible Bengaluru hiring ecosystem; verify role location | F15: Global enterprise; check latest Fortune US 500 / Global 500 / 1000 lists | G15: Business operations; process associate; PMO; procurement; finance operations; HR operations; workforce coordination; client/service delivery support; research; digital marketing operations | H15: P1 - start here | I15: https://www.genpact.com/careers | J15: Official careers page | K15: https://www.google.com/search?q=Genpact+Bengaluru+Bangalore+entry+level+careers+operations+procurement+HR+jobs | L15: Company target only - no current vacancy independently verified in company-universe scan | M15: Not checked in this build | O15: Re-check every 7 days; check official portal first, then ATS / LinkedIn / job boards | P15: Company target only; this row is not proof of a live vacancy. Search exact Bengaluru location, filter by 0-2 years and degree eligibility, then record a verified requisition in Live Jobs.
A16: CO-0012 | B16: Concentrix | C16: IT Services, Consulting & BPO | D16: MNC / professional services | E16: Strong or plausible Bengaluru hiring ecosystem; verify role location | F16: Global enterprise; check latest Fortune US 500 / Global 500 / 1000 lists | G16: Business operations; process associate; PMO; procurement; finance operations; HR operations; workforce coordination; client/service delivery support; research; digital marketing operations | H16: P1 | I16: https://jobs.concentrix.com/global/en | J16: Official careers page | K16: https://www.google.com/search?q=Concentrix+Bengaluru+Bangalore+entry+level+careers+operations+procurement+HR+jobs | L16: Company target only - no current vacancy independently verified in company-universe scan | M16: Not checked in this build | O16: Re-check every 7 days; check official portal first, then ATS / LinkedIn / job boards | P16: Company target only; this row is not proof of a live vacancy. Search exact Bengaluru location, filter by 0-2 years and degree eligibility, then record a verified requisition in Live Jobs.
... A510: CO-0506 | B510: SIDBI | C510: Public Sector, Infrastructure & Utilities | D510: Public sector / infrastructure | E510: Regional/national employer; confirm Bengaluru-specific site or role | F510: Indian enterprise / public-sector target; not a Fortune claim | G510: Operations support; procurement; admin; project coordination; vendor management; documentation; HR; finance/accounts operations; apprenticeships and graduate trainee roles | H510: P2 | I510: https://www.google.com/search?q=SIDBI+official+careers+Bengaluru+jobs | J510: Search shortcut - verify official portal | K510: https://www.google.com/search?q=SIDBI+Bengaluru+Bangalore+entry+level+careers+operations+procurement+HR+jobs | L510: Company target only - no current vacancy independently verified in company-universe scan | M510: Not checked in this build | O510: Re-check every 7 days; check official portal first, then ATS / LinkedIn / job boards | P510: Company target only; this row is not proof of a live vacancy. Search exact Bengaluru location, filter by 0-2 years and degree eligibility, then record a verified requisition in Live Jobs. Careers URL is a search shortcut, not the employer's own portal.

Sheet Role Taxonomy
A1: ROLE TAXONOMY | BBA-FRIENDLY NON-SALES PATHWAYS
A2: Use these families to generate separate, precise searches. Eligibility is role-specific; verify every job description.
A4: Role Family / Title | B4: Priority | C4: Typical Entry Eligibility | D4: Core Responsibilities | E4: Search Title Variants | F4: Likely Skills / Keywords | G4: Fit for Candidate Preference | H4: Screening Notes
A5: Business Operations Associate | B5: P1 | C5: BBA/any graduation; 0-2 years | D5: Process tracking, dashboards, cross-functional coordination, SOPs, issue handling | E5: business operations associate; operations executive; operations analyst; process associate | F5: Excel; documentation; reporting; ownership; communication | G5: High | H5: Avoid roles that hide hard sales quotas under 'operations'.
A6: Procurement / Purchase Associate | B6: P1 | C6: Any graduation/BBA/B.Com depending on JD | D6: Purchase orders, supplier follow-up, invoice matching, requisitions, sourcing support | E6: procurement new associate; purchase associate; procurement operations; purchasing coordinator | F6: Excel; vendor management; P2P basics; accuracy | G6: High | H6: Prefer requisition/P2P support roles; avoid requiring engineering/category experience if not eligible.
A7: Supplier Onboarding / Vendor Management | B7: P1 | C7: BBA/any graduation; internships may count | D7: Vendor documentation, due diligence, portals, onboarding checklist, compliance, trackers | E7: supplier onboarding associate; vendor onboarding; vendor operations | F7: Excel; documentation; written communication; tracking | G7: High | H7: Confirm shift, work mode and client-facing requirements.
A8: Supply Chain Coordinator | B8: P1 | C8: BBA/SCM/logistics accepted in some roles | D8: Order tracking, inventory tracking, supplier communication, logistics coordination | E8: supply chain associate; SCM coordinator; logistics coordinator | F8: Excel; follow-up; data accuracy; coordination | G8: High | H8: Some roles request engineering/supply chain degree; confirm education.
A9: PMO Analyst / Project Coordinator | B9: P1 | C9: Any graduate for coordinator roles; PMO analyst may require Excel/reporting | D9: Project status, minutes, trackers, RAID logs, scheduling, stakeholder updates | E9: PMO analyst; project coordinator; project support associate | F9: Excel; PowerPoint; planning; communication | G9: High | H9: Do not target IT PMO roles that require technical project experience unless entry-level.
A10: HR Operations / People Operations | B10: P1 | C10: BBA/HR/any graduation depending on company | D10: Employee records, onboarding, HR ticketing, HR administration, data reports | E10: HR operations associate; people operations coordinator; HR apprentice | F10: Excel; discretion; organization; communication | G10: High | H10: Recruitment internships may be a stepping stone; check whether role is cold-calling candidates.
A11: Recruitment Coordination / TA Operations | B11: P2 | C11: BBA often accepted; coordinator experience useful | D11: Scheduling, applicant tracking, onboarding docs, candidate communication | E11: recruitment coordinator; talent operations; interview scheduler | F11: Calendar management; ATS familiarity; follow-up | G11: Medium | H11: Avoid commission-only recruiting or sales-style staffing jobs.
A12: Finance Operations / Procure-to-Pay | B12: P1 | C12: Any graduation/BBA/B.Com depending on posting | D12: Invoice processing, reconciliations, AP/AR support, vendor payment queues | E12: P2P new associate; accounts payable associate; finance operations associate | F12: Excel; numbers; accuracy; process controls | G12: High | H12: Some finance roles need accounting qualifications. Check rotation shifts.
A13: Risk / Compliance / KYC Operations | B13: P1/P2 | C13: BBA/commerce often accepted for junior ops; exact degree varies | D13: Document review, quality/risk checks, regulatory research, exception escalation | E13: quality and risk management associate; KYC analyst; compliance operations associate | F13: Research; attention to detail; written communication | G13: High | H13: KYC/AML roles may require specific experience; never claim certification you don't hold.
A14: Research / Due Diligence Associate | B14: P2 | C14: Any graduate in some firms; writing/research strength required | D14: Company research, regulatory databases, corporate registry searches, briefings | E14: business research associate; due diligence associate; analyst support | F14: Desk research; Excel; summarisation; source evaluation | G14: High | H14: Some roles need law/finance or language skills.
A15: Customer Operations (non-sales) | B15: P2 | C15: BBA/any graduate; fresher roles common | D15: Email/chat cases, order queries, issue resolution, customer records | E15: customer operations associate; customer support email chat; service delivery associate | F15: Written communication; troubleshooting; CRM; accuracy | G15: Medium | H15: Filter out business development, telesales, lead generation, cross-sell and upsell quotas.
... A43: International Business / Global Trade Support | B43: P2 | C43: BBA International Business is relevant when a role permits graduate entry | D43: Global orders, trade documentation, sourcing, cross-border coordination | E43: global business operations; trade support associate | F43: Documentation; communication; Excel; global awareness | G43: Medium | H43: Often niche; confirm required language and trade compliance experience.

Sheet Search Sources
A1: SEARCH PORTALS & RESEARCH SOURCES
A2: Run the scan across sources and maintain dates/result counts. Last initial scan date: 2026-10-11.
A4: Source / Portal | B4: Type | C4: URL / Starting Point | D4: Query & Filters to Use | E4: Validation Method | F4: Evidence Quality | G4: How to Use It | H4: Limitations / Warnings
A5: Official company portals | B5: Primary evidence | C5: Employer-specific official career portal | D5: Search role terms + Bengaluru/Bangalore + entry-level/graduate/0-2 years | E5: Always inspect the exact job page | F5: Highest | G5: Search before referral; capture official requisition ID | H5: https://www.google.com/search?q=official+company+careers+Bengaluru
A6: LinkedIn Jobs | B6: Public secondary source | C6: Jobs search | D6: Bengaluru + BBA fresher + role family; set date posted past week/month | E6: Open company job page; find company req ID in official portal | F6: High discovery, verify ID internally | G6: Do not treat LinkedIn job ID as internal requisition | H6: https://www.linkedin.com/jobs/
A7: Indeed India | B7: Public secondary source | C7: Jobs search | D7: Bengaluru business operations / procurement / HR ops / finance operations | E7: Distinguish direct employer listing from agency/redirect | F7: High discovery, verify freshness | G7: Indeed internal result tokens are not public job IDs | H7: https://in.indeed.com/
A8: Naukri | B8: Public secondary source | C8: Jobs search | D8: Bengaluru + fresher / 0-2 years + exact title; filter non-sales | E8: Prefer employer careers page for final status | F8: High discovery, verify ID | G8: Avoid job consultancy fee requests | H8: https://www.naukri.com/
A9: Foundit | B9: Public secondary source | C9: Jobs search | D9: Bangalore + early careers, shared services, operations, procurement | E9: Open full JD and capture post date | F9: High discovery, verify ID | G9: Check agency and employer name carefully | H9: https://www.foundit.in/
A10: Apna | B10: India job aggregator | C10: Jobs search | D10: Bangalore + fresher + operations/procurement/HR/purchase | E10: Fetch full job details and use public ID only as a public listing ID | F10: Medium-high discovery | G10: Does not guarantee an official requisition ID | H10: https://apna.co/
A11: Internshala Jobs | B11: Early career source | C11: Jobs search | D11: Bangalore + Operations, SCM, HR, Finance, General Management; experience 0 | E11: Record salary, applicants, posted age and embedded listing reference | F11: Medium-high discovery | G11: Verify startup/employer and exact scope, especially manager titles marked fresher | H11: https://internshala.com/jobs/
A12: Wellfound | B12: Startup jobs | C12: Startup hiring | D12: Bengaluru + operations/business/people/procurement; early career | E12: Verify current location and official apply destination | F12: Medium-high discovery | G12: Funding/company stage does not prove an active role | H12: https://wellfound.com/jobs
A13: Cutshort | B13: Startup/tech jobs | C13: Startup hiring | D13: Bangalore + operations/project coordinator/customer operations | E13: Use roles where business skills are central | F13: Medium discovery | G13: Confirm employer and whether tech degree is required | H13: https://cutshort.io/jobs
A14: Instahyre | B14: Startup/tech jobs | C14: Jobs search | D14: Bengaluru + business operations/customer success/people ops | E14: Filter experience; open employer portal | F14: Medium discovery | G14: Some listings skew technical or experienced | H14: https://www.instahyre.com/
A15: iimjobs | B15: Professional roles | C15: Jobs search | D15: Bengaluru + operations/PMO/marketing operations; filter fresher/early career | E15: Likely lower coverage for fresh BBA; use selectively | F15: Medium-low | G15: Many postings require MBA/experience | H15: https://www.iimjobs.com/
... A28: Startup funding / portfolio pages | B28: Startup universe research | C28: Startup intelligence | D28: Company newsrooms, investor portfolios, credible business press | E28: Funding is only a target-priority signal | F28: Secondary research | G28: Funding does not prove hiring | H28: https://www.ycombinator.com/

Sheet ATS Portal Map
A1: ATS & JOB-ID VERIFICATION MAP
A2: The same job may appear on several sites. Record the official requisition separately from the public platform ID.
A4: ATS / Portal | B4: Type | C4: Pattern / Link | D4: How to Extract ID and Verify | E4: Evidence Rule
A5: Workday | B5: ATS provider | C5: Company-specific Workday tenants such as company.wd5.myworkdayjobs.com | D5: Use exact company tenant + job title/location; save requisition code from full posting | E5: Official only if tenant is employer-confirmed
A6: SmartRecruiters | B6: ATS provider | C6: jobs.smartrecruiters.com/CompanyName/PostingID | D6: Posting ID often in URL; save title and exact company account | E6: Official if employer account is verified
A7: Greenhouse | B7: ATS provider | C7: boards.greenhouse.io/company/jobs/ID | D7: Job ID embedded in URL / posting page | E7: Official if company board is verified
A8: Lever | B8: ATS provider | C8: jobs.lever.co/company/ID | D8: UUID or job page identifier; record as ATS posting ID | E8: Official if company account verified
A9: SAP SuccessFactors | B9: ATS provider | C9: Company's official recruiting subdomain | D9: Search title + city; identifier may be requisition number, posting ID or application code | E9: Check employer domain
A10: Oracle / Taleo | B10: ATS provider | C10: Company-branded Oracle recruiting page | D10: Record requisition number from job detail, not search token | E10: Check employer domain
A11: iCIMS | B11: ATS provider | C11: jobs.company.com or careers-company.icims.com | D11: Record req ID in exact posting | E11: Check employer domain
A12: Workable | B12: ATS provider | C12: apply.workable.com/company | D12: Record unique posting link and any role ID shown | E12: Check employer domain
A13: LinkedIn Jobs | B13: Public job board | C13: linkedin.com/jobs/view/TITLE-ID | D13: LinkedIn ID is a public listing ID, not necessarily internal req ID | E13: Request company internal ID from employee
A14: Naukri / Indeed / Apna / Internshala | B14: Public job boards | C14: Platform-specific result pages | D14: Keep public listing ID separate; prefer direct official link for referral | E14: Search-board evidence only if no official page found

Sheet Application Tracker
A1: APPLICATION & REFERRAL TRACKER
A2: Start one row per application. Dropdowns keep statuses consistent; enter real dates and do not mark a referral complete until the employee confirms.
A4: Track ID | B4: Date Added | C4: Company | D4: Role | E4: Official Req ID | F4: Apply URL | G4: Resume Version | H4: Applied? | I4: Application Date | J4: Referral Contact | K4: LinkedIn URL | L4: Referral Asked? | M4: Referral Date | N4: Reply / Referral Status | O4: Last Follow-up | P4: Next Follow-up | Q4: Interview Stage | R4: Next Action | S4: Notes
A5: APP-001 | G5: BBA-IB CV v1 | H5: Not Started | L5: Not Contacted
A6: APP-002 | G6: BBA-IB CV v1 | H6: Not Started | L6: Not Contacted
A7: APP-003 | G7: BBA-IB CV v1 | H7: Not Started | L7: Not Contacted
A8: APP-004 | G8: BBA-IB CV v1 | H8: Not Started | L8: Not Contacted
A9: APP-005 | G9: BBA-IB CV v1 | H9: Not Started | L9: Not Contacted
A10: APP-006 | G10: BBA-IB CV v1 | H10: Not Started | L10: Not Contacted
A11: APP-007 | G11: BBA-IB CV v1 | H11: Not Started | L11: Not Contacted
A12: APP-008 | G12: BBA-IB CV v1 | H12: Not Started | L12: Not Contacted
A13: APP-009 | G13: BBA-IB CV v1 | H13: Not Started | L13: Not Contacted
A14: APP-010 | G14: BBA-IB CV v1 | H14: Not Started | L14: Not Contacted
A15: APP-011 | G15: BBA-IB CV v1 | H15: Not Started | L15: Not Contacted
A16: APP-012 | G16: BBA-IB CV v1 | H16: Not Started | L16: Not Contacted
... A54: APP-050 | G54: BBA-IB CV v1 | H54: Not Started | L54: Not Contacted

Sheet Referral Messages
A1: LINKEDIN REFERRAL MESSAGE LIBRARY
A2: Use official requisition IDs where available. When only an aggregator ID exists, say so clearly and ask the employee to locate the internal requisition.
A4: Message Type | B4: Best Use | C4: Copy-ready Draft
A5: Message Type | B5: Best use | C5: Copy-ready draft
A6: Referral request - official req ID | B6: Use when an internal requisition ID is verified | C6: Hi [Name], I’m a BBA graduate specialising in International Business and I’m looking for an entry-level role in Bengaluru in business operations, procurement, supply chain or project coordination. I found this role: [Role Title], [Official Req ID]. Would you be comfortable checking whether it is open in your internal referral portal and referring me if my profile fits? I have practical experience in event/campaign coordination, team supervision and business operations, and I’m happy to send my CV. Thank you for your time.
A7: Referral request - only public listing ID | B7: Use for Apna/LinkedIn/Indeed/Internshala listing without internal req | C7: Hi [Name], I found this public listing for [Role Title] at [Company]: [URL]. The public listing reference is [Public ID], which may not be the internal requisition ID. Could you please check whether the same role is open in your company’s referral portal and share the internal req ID if available? I’m a BBA International Business graduate and am targeting non-sales operations/procurement/coordinator roles in Bengaluru. I can share my CV. Thank you!
A8: Recruiter first message | B8: Send to a recruiter/hiring contact from a public professional profile | C8: Hello [Name], I’m a BBA graduate specialising in International Business and am exploring entry-level roles in Bengaluru in operations, procurement, supply chain, HR operations or project coordination. My practical experience includes event/campaign execution, team supervision and stakeholder coordination. I’m interested in [role/company] and can share my CV if there is a suitable opening. Thank you for your time.
A9: After applying | B9: Use after an online application or employee referral | C9: Hi [Name], thank you for referring/helping me with [Role Title, Req ID]. I’ve submitted my application on [date]. I’ll keep you updated if I receive an assessment or interview invitation. I appreciate your support.
A10: Follow-up after 5-7 days | B10: One polite follow-up, then pause | C10: Hi [Name], I wanted to politely follow up on [Role Title, Req ID] and check whether the opening is still active or whether any additional information is needed from me. No worries if the team has already progressed. Thank you again for your help.
